<?xml version="1.0"?>
<robot name="neurobot" xmlns:xacro="http://www.ros.org/wiki/xacro">
  <xacro:property name="wheel_radius" value="0.09"/>
  <xacro:property name="wheel_length" value="0.04"/>
  <xacro:property name="wheel_separation" value="0.38"/>

  <material name="graphite"><color rgba="0.15 0.16 0.18 1.0"/></material>
  <material name="accent"><color rgba="0.22 0.44 0.72 1.0"/></material>

  <link name="base_link">
    <visual><origin xyz="0 0 0"/><geometry><box size="0.50 0.34 0.16"/></geometry><material name="graphite"/></visual>
    <collision><origin xyz="0 0 0"/><geometry><box size="0.50 0.34 0.16"/></geometry></collision>
    <inertial><origin xyz="0 0 0"/><mass value="6.0"/><inertia ixx="0.10" ixy="0" ixz="0" iyy="0.12" iyz="0" izz="0.14"/></inertial>
  </link>

  <link name="base_footprint"/>
  <joint name="base_footprint_joint" type="fixed">
    <parent link="base_footprint"/>
    <child link="base_link"/>
    <origin xyz="0 0 0.08" rpy="0 0 0"/>
  </joint>

  <link name="left_wheel_link">
    <visual><origin rpy="1.57079632679 0 0"/><geometry><cylinder radius="${wheel_radius}" length="${wheel_length}"/></geometry><material name="accent"/></visual>
    <collision><origin rpy="1.57079632679 0 0"/><geometry><cylinder radius="${wheel_radius}" length="${wheel_length}"/></geometry></collision>
    <inertial><mass value="0.4"/><origin xyz="0 0 0"/><inertia ixx="0.001" ixy="0" ixz="0" iyy="0.001" iyz="0" izz="0.001"/></inertial>
  </link>
  <joint name="left_wheel_joint" type="continuous">
    <parent link="base_link"/>
    <child link="left_wheel_link"/>
    <origin xyz="0 ${wheel_separation/2} -0.02" rpy="0 0 0"/>
    <axis xyz="0 1 0"/>
  </joint>

  <link name="right_wheel_link">
    <visual><origin rpy="1.57079632679 0 0"/><geometry><cylinder radius="${wheel_radius}" length="${wheel_length}"/></geometry><material name="accent"/></visual>
    <collision><origin rpy="1.57079632679 0 0"/><geometry><cylinder radius="${wheel_radius}" length="${wheel_length}"/></geometry></collision>
    <inertial><mass value="0.4"/><origin xyz="0 0 0"/><inertia ixx="0.001" ixy="0" ixz="0" iyy="0.001" iyz="0" izz="0.001"/></inertial>
  </link>
  <joint name="right_wheel_joint" type="continuous">
    <parent link="base_link"/>
    <child link="right_wheel_link"/>
    <origin xyz="0 -${wheel_separation/2} -0.02" rpy="0 0 0"/>
    <axis xyz="0 1 0"/>
  </joint>

  <link name="lidar_link"/>
  <joint name="lidar_joint" type="fixed">
    <parent link="base_link"/>
    <child link="lidar_link"/>
    <origin xyz="0.18 0 0.10" rpy="0 0 0"/>
  </joint>

  <link name="imu_link"/>
  <joint name="imu_joint" type="fixed">
    <parent link="base_link"/>
    <child link="imu_link"/>
    <origin xyz="0 0 0.05" rpy="0 0 0"/>
  </joint>

  <link name="camera_link"/>
  <joint name="camera_joint" type="fixed">
    <parent link="base_link"/>
    <child link="camera_link"/>
    <origin xyz="0.20 0 0.12" rpy="0 0 0"/>
  </joint>

  <link name="depth_camera_link"/>
  <joint name="depth_camera_joint" type="fixed">
    <parent link="base_link"/>
    <child link="depth_camera_link"/>
    <origin xyz="0.18 0 0.13" rpy="0 0 0"/>
  </joint>

  <link name="contact_front_link"/>
  <joint name="contact_front_joint" type="fixed">
    <parent link="base_link"/>
    <child link="contact_front_link"/>
    <origin xyz="0.26 0 0.01" rpy="0 0 0"/>
  </joint>

  <ros2_control name="neurobot_system" type="system">
    <hardware>
      <plugin>gz_ros2_control/GazeboSimSystem</plugin>
    </hardware>
    <joint name="left_wheel_joint">
      <command_interface name="velocity"/>
      <state_interface name="position"/>
      <state_interface name="velocity"/>
    </joint>
    <joint name="right_wheel_joint">
      <command_interface name="velocity"/>
      <state_interface name="position"/>
      <state_interface name="velocity"/>
    </joint>
  </ros2_control>

  <gazebo>
    <plugin filename="libgz_ros2_control-system.so" name="gz_ros2_control::GazeboSimROS2ControlPlugin">
      <parameters>$(find neuro_nav_bringup)/config/ros2_controllers.yaml</parameters>
    </plugin>
  </gazebo>

  <gazebo reference="lidar_link">
    <sensor name="front_lidar" type="gpu_lidar">
      <always_on>true</always_on>
      <update_rate>20</update_rate>
      <topic>/scan</topic>
      <gz_frame_id>lidar_link</gz_frame_id>
      <lidar>
        <scan><horizontal><samples>720</samples><resolution>1</resolution><min_angle>-3.14159</min_angle><max_angle>3.14159</max_angle></horizontal></scan>
        <range><min>0.08</min><max>12.0</max><resolution>0.01</resolution></range>
      </lidar>
    </sensor>
  </gazebo>

  <gazebo reference="imu_link">
    <sensor name="imu_sensor" type="imu">
      <always_on>true</always_on>
      <update_rate>100</update_rate>
      <topic>/imu/data</topic>
      <gz_frame_id>imu_link</gz_frame_id>
    </sensor>
  </gazebo>

  <gazebo reference="camera_link">
    <sensor name="rgb_camera" type="camera">
      <always_on>true</always_on>
      <update_rate>15</update_rate>
      <topic>/camera/image_raw</topic>
      <gz_frame_id>camera_link</gz_frame_id>
      <camera>
        <horizontal_fov>1.396</horizontal_fov>
        <image><width>640</width><height>480</height><format>R8G8B8</format></image>
        <clip><near>0.05</near><far>25.0</far></clip>
      </camera>
    </sensor>
  </gazebo>

  <gazebo reference="depth_camera_link">
    <sensor name="depth_camera" type="depth_camera">
      <always_on>true</always_on>
      <update_rate>10</update_rate>
      <topic>/camera/depth/image_raw</topic>
      <gz_frame_id>depth_camera_link</gz_frame_id>
      <camera>
        <horizontal_fov>1.2217</horizontal_fov>
        <image><width>424</width><height>240</height><format>R_FLOAT32</format></image>
        <clip><near>0.1</near><far>15.0</far></clip>
      </camera>
    </sensor>
  </gazebo>

  <gazebo reference="contact_front_link">
    <sensor name="front_contact" type="contact">
      <always_on>true</always_on>
      <update_rate>50</update_rate>
      <topic>/bumper/contact</topic>
    </sensor>
  </gazebo>
</robot>
